Workbook

Sheet Dashboard
AA1: Currency | AB1: Display
B2: FINANCIAL DASHBOARD 2026 | I2: VIEW: | K2: ALL TIME | M2: CURRENCY: | N2: CZK | O2: FREELANCE EARNINGS BY CURRENCY | AA2: CZK | AB2: CZK
B3: January 1st - December 31st, 2026 | O3: Currency | P3: Total Earned | Q3: Months | R3: Avg/Month | S3: % of Total | AA3: USD | AB3: USD
O4: CZK | P4: =IF('January 2026'!I6="CZK",'January 2026'!G6,0)+IF('February 2026'!I6="CZK",'February 2026'!G6,0)+IF('March 2026'!I6="CZK",'March 2026'!G6,0)+IF('April 2026'!I6="CZK",'April 2026'!G6,0)+IF('May 2026'!I6="CZK",'May 2026'!G6,0)+IF('June 2026'!I6="CZK",'June 2026'!G6,0)+IF('July 2026'!I6="CZK",'July 2026'!G6,0)+IF('August 2026'!I6="CZK",'August 2026'!G6,0)+IF('September 2026'!I6="CZK",'September 2026'!G6,0)+IF('October 2026'!I6="CZK",'October 2026'!G6,0)+IF('November 2026'!I6="CZK",'November 2026'!G6,0)+IF('December 2026'!I6="CZK",'December 2026'!G6,0) -> 0 | Q4: =IF('January 2026'!I6="CZK",1,0)+IF('February 2026'!I6="CZK",1,0)+IF('March 2026'!I6="CZK",1,0)+IF('April 2026'!I6="CZK",1,0)+IF('May 2026'!I6="CZK",1,0)+IF('June 2026'!I6="CZK",1,0)+IF('July 2026'!I6="CZK",1,0)+IF('August 2026'!I6="CZK",1,0)+IF('September 2026'!I6="CZK",1,0)+IF('October 2026'!I6="CZK",1,0)+IF('November 2026'!I6="CZK",1,0)+IF('December 2026'!I6="CZK",1,0) -> 0 | R4: =IFERROR(IF(Q4>0,P4/Q4,0),0) -> 0 | S4: =IFERROR(IF(P8>0,P4/P8,0),0) -> 0 | AA4: EUR | AB4: EUR
B5: Tracking Period: | C5: January 1, 2026 - December 31, 2026 | F5: Total Days: | G5: 365 | I5: All values in: | J5: =$N$2 -> 0 | O5: USD | P5: =IF('January 2026'!I6="USD",'January 2026'!G6,0)+IF('February 2026'!I6="USD",'February 2026'!G6,0)+IF('March 2026'!I6="USD",'March 2026'!G6,0)+IF('April 2026'!I6="USD",'April 2026'!G6,0)+IF('May 2026'!I6="USD",'May 2026'!G6,0)+IF('June 2026'!I6="USD",'June 2026'!G6,0)+IF('July 2026'!I6="USD",'July 2026'!G6,0)+IF('August 2026'!I6="USD",'August 2026'!G6,0)+IF('September 2026'!I6="USD",'September 2026'!G6,0)+IF('October 2026'!I6="USD",'October 2026'!G6,0)+IF('November 2026'!I6="USD",'November 2026'!G6,0)+IF('December 2026'!I6="USD",'December 2026'!G6,0) -> 0 | Q5: =IF('January 2026'!I6="USD",1,0)+IF('February 2026'!I6="USD",1,0)+IF('March 2026'!I6="USD",1,0)+IF('April 2026'!I6="USD",1,0)+IF('May 2026'!I6="USD",1,0)+IF('June 2026'!I6="USD",1,0)+IF('July 2026'!I6="USD",1,0)+IF('August 2026'!I6="USD",1,0)+IF('September 2026'!I6="USD",1,0)+IF('October 2026'!I6="USD",1,0)+IF('November 2026'!I6="USD",1,0)+IF('December 2026'!I6="USD",1,0) -> 0 | R5: =IFERROR(IF(Q5>0,P5/Q5,0),0) -> 0 | S5: =IFERROR(IF(P8>0,P5/P8,0),0) -> 0 | AA5: NGN | AB5: NGN
O6: EUR | P6: =IF('January 2026'!I6="EUR",'January 2026'!G6,0)+IF('February 2026'!I6="EUR",'February 2026'!G6,0)+IF('March 2026'!I6="EUR",'March 2026'!G6,0)+IF('April 2026'!I6="EUR",'April 2026'!G6,0)+IF('May 2026'!I6="EUR",'May 2026'!G6,0)+IF('June 2026'!I6="EUR",'June 2026'!G6,0)+IF('July 2026'!I6="EUR",'July 2026'!G6,0)+IF('August 2026'!I6="EUR",'August 2026'!G6,0)+IF('September 2026'!I6="EUR",'September 2026'!G6,0)+IF('October 2026'!I6="EUR",'October 2026'!G6,0)+IF('November 2026'!I6="EUR",'November 2026'!G6,0)+IF('December 2026'!I6="EUR",'December 2026'!G6,0) -> 0 | Q6: =IF('January 2026'!I6="EUR",1,0)+IF('February 2026'!I6="EUR",1,0)+IF('March 2026'!I6="EUR",1,0)+IF('April 2026'!I6="EUR",1,0)+IF('May 2026'!I6="EUR",1,0)+IF('June 2026'!I6="EUR",1,0)+IF('July 2026'!I6="EUR",1,0)+IF('August 2026'!I6="EUR",1,0)+IF('September 2026'!I6="EUR",1,0)+IF('October 2026'!I6="EUR",1,0)+IF('November 2026'!I6="EUR",1,0)+IF('December 2026'!I6="EUR",1,0) -> 0 | R6: =IFERROR(IF(Q6>0,P6/Q6,0),0) -> 0 | S6: =IFERROR(IF(P8>0,P6/P8,0),0) -> 0
B7: ACCOUNT BALANCE TRACKING | I7: TOP SPENDING CATEGORIES (YTD) | O7: NGN | P7: =IF('January 2026'!I6="NGN",'January 2026'!G6,0)+IF('February 2026'!I6="NGN",'February 2026'!G6,0)+IF('March 2026'!I6="NGN",'March 2026'!G6,0)+IF('April 2026'!I6="NGN",'April 2026'!G6,0)+IF('May 2026'!I6="NGN",'May 2026'!G6,0)+IF('June 2026'!I6="NGN",'June 2026'!G6,0)+IF('July 2026'!I6="NGN",'July 2026'!G6,0)+IF('August 2026'!I6="NGN",'August 2026'!G6,0)+IF('September 2026'!I6="NGN",'September 2026'!G6,0)+IF('October 2026'!I6="NGN",'October 2026'!G6,0)+IF('November 2026'!I6="NGN",'November 2026'!G6,0)+IF('December 2026'!I6="NGN",'December 2026'!G6,0) -> 0 | Q7: =IF('January 2026'!I6="NGN",1,0)+IF('February 2026'!I6="NGN",1,0)+IF('March 2026'!I6="NGN",1,0)+IF('April 2026'!I6="NGN",1,0)+IF('May 2026'!I6="NGN",1,0)+IF('June 2026'!I6="NGN",1,0)+IF('July 2026'!I6="NGN",1,0)+IF('August 2026'!I6="NGN",1,0)+IF('September 2026'!I6="NGN",1,0)+IF('October 2026'!I6="NGN",1,0)+IF('November 2026'!I6="NGN",1,0)+IF('December 2026'!I6="NGN",1,0) -> 0 | R7: =IFERROR(IF(Q7>0,P7/Q7,0),0) -> 0 | S7: =IFERROR(IF(P8>0,P7/P8,0),0) -> 0
B8: Opening Balance (Jan 1) | C8: 0 | I8: Category | J8: Budget | K8: Spent | L8: Status | M8: % Used | O8: TOTAL | P8: =SUM(P4:P7) -> 0 | Q8: =SUM(Q4:Q7) -> 0 | R8: =IFERROR(IF(Q8>0,P8/Q8,0),0) -> 0 | S8: =IFERROR(SUM(S4:S7),0) -> 0
B9: Current/Closing Balance | C9: 0 | I9: Rent + Utilities | J9: ='Monthly Budget'!D3*12 -> 0 | K9: ='Budget vs Actual'!D3 -> 0 | L9: =IF(K9>J9,"Over",IF(K9>J9*0.9,"Warn","OK")) -> 0 | M9: =IFERROR(IF(J9>0,K9/J9,0),0) -> 0
B10: Net Change (YTD) | C10: =C9-C8 -> 0 | I10: Electricity Deposit | J10: ='Monthly Budget'!D4*12 -> 0 | K10: ='Budget vs Actual'!D4 -> 0 | L10: =IF(K10>J10,"Over",IF(K10>J10*0.9,"Warn","OK")) -> 0 | M10: =IFERROR(IF(J10>0,K10/J10,0),0) -> 0
B11: Target Savings (Monthly) | C11: 5,000 - 10,000 | I11: Internet & Phone Bills | J11: ='Monthly Budget'!D5*12 -> 0 | K11: ='Budget vs Actual'!D5 -> 0 | L11: =IF(K11>J11,"Over",IF(K11>J11*0.9,"Warn","OK")) -> 0 | M11: =IFERROR(IF(J11>0,K11/J11,0),0) -> 0
B12: Financial Discipline Score | C12: =IF(C8=0,"Enter Opening Balance",IF(C10>=10000,"Excellent",IF(C10>=5000,"Good","Needs Attention"))) -> 0 | I12: Food & Groceries | J12: ='Monthly Budget'!D6*12 -> 0 | K12: ='Budget vs Actual'!D6 -> 0 | L12: =IF(K12>J12,"Over",IF(K12>J12*0.9,"Warn","OK")) -> 0 | M12: =IFERROR(IF(J12>0,K12/J12,0),0) -> 0
I13: Investments | J13: ='Monthly Budget'!D7*12 -> 0 | K13: ='Budget vs Actual'!D7 -> 0 | L13: =IF(K13>J13,"Over",IF(K13>J13*0.9,"Warn","OK")) -> 0 | M13: =IFERROR(IF(J13>0,K13/J13,0),0) -> 0
B14: KEY FINANCIAL METRICS (YEAR-TO-DATE) | I14: Date Nights | J14: ='Monthly Budget'!D8*12 -> 0 | K14: ='Budget vs Actual'!D8 -> 0 | L14: =IF(K14>J14,"Over",IF(K14>J14*0.9,"Warn","OK")) -> 0 | M14: =IFERROR(IF(J14>0,K14/J14,0),0) -> 0
B15: Annual Budget | C15: YTD Spent | D15: Remaining | E15: Budget Used | F15: YTD Savings | G15: Months Active | I15: Annual Costs Savings | J15: ='Monthly Budget'!D9*12 -> 0 | K15: ='Budget vs Actual'!D9 -> 0 | L15: =IF(K15>J15,"Over",IF(K15>J15*0.9,"Warn","OK")) -> 0 | M15: =IFERROR(IF(J15>0,K15/J15,0),0) -> 0
B16: =IFERROR('Monthly Budget'!D14*12,0) -> 0 | C16: =IFERROR('Annual Summary'!E16,0) -> 0 | D16: =IFERROR(B16-C16,0) -> 0 | E16: =IFERROR(IF(B16>0,C16/B16,0),0) -> 0 | F16: =IFERROR(C10,0) -> 0 | G16: =IFERROR(COUNTIF('Annual Summary'!E4:E15,">0"),0) -> 0 | I16: Emergency Buffer | J16: ='Monthly Budget'!D10*12 -> 0 | K16: ='Budget vs Actual'!D10 -> 0 | L16: =IF(K16>J16,"Over",IF(K16>J16*0.9,"Warn","OK")) -> 0 | M16: =IFERROR(IF(J16>0,K16/J16,0),0) -> 0
B18: BUDGET ALERT STATUS | I18: MONTHLY EXPENSE SHEETS
B19: =IF(E16>1,"ALERT: You have exceeded your annual budget! Review expenses immediately.",IF(E16>0.9,"WARNING: You have used over 90% of your annual budget.",IF(E16>0.75,"CAUTION: You have used over 75% of your annual budget.","ON TRACK: Your spending is within budget."))) -> 0 | I19: Each month (Jan-Dec) has pre-populated dates Navigate to monthly sheets to log daily expenses
B22: 2026 MONTHLY EXPENSE SUMMARY | I22: INCOME TRACKER (Salary + Freelance)
B23: Jan | C23: Feb | D23: Mar | E23: Apr | F23: May | G23: Jun | I23: Month | J23: Salary | K23: Freelance | L23: Total Income | M23: YTD Freelance
B24: ='January 2026'!G41 -> 0 | C24: ='February 2026'!G38 -> 0 | D24: ='March 2026'!G41 -> 0 | E24: ='April 2026'!G40 -> 0 | F24: ='May 2026'!G41 -> 0 | G24: ='June 2026'!G40 -> 0 | I24: Jan | J24: ='January 2026'!G5 -> 0 | K24: ='January 2026'!G6 -> 0 | L24: ='January 2026'!G7 -> 0 | M24: =K24 -> 0
B25: Jul | C25: Aug | D25: Sep | E25: Oct | F25: Nov | G25: Dec | I25: Feb | J25: ='February 2026'!G5 -> 0 | K25: ='February 2026'!G6 -> 0 | L25: ='February 2026'!G7 -> 0 | M25: =M24+K25 -> 0
B26: ='July 2026'!G41 -> 0 | C26: ='August 2026'!G41 -> 0 | D26: ='September 2026'!G40 -> 0 | E26: ='October 2026'!G41 -> 0 | F26: ='November 2026'!G40 -> 0 | G26: ='December 2026'!G41 -> 0 | I26: Mar | J26: ='March 2026'!G5 -> 0 | K26: ='March 2026'!G6 -> 0 | L26: ='March 2026'!G7 -> 0 | M26: =M25+K26 -> 0
I27: Apr | J27: ='April 2026'!G5 -> 0 | K27: ='April 2026'!G6 -> 0 | L27: ='April 2026'!G7 -> 0 | M27: =M26+K27 -> 0
B28: MONTHLY SURPLUS TRACKER (Budget Savings + Freelance) | I28: May | J28: ='May 2026'!G5 -> 0 | K28: ='May 2026'!G6 -> 0 | L28: ='May 2026'!G7 -> 0 | M28: =M27+K28 -> 0
B29: Month | C29: Budget | D29: Spent | E29: Savings | F29: Freelance | G29: Total Surplus | I29: Jun | J29: ='June 2026'!G5 -> 0 | K29: ='June 2026'!G6 -> 0 | L29: ='June 2026'!G7 -> 0 | M29: =M28+K29 -> 0
B30: Jan | C30: ='Monthly Budget'!D14 -> 0 | D30: ='January 2026'!G41 -> 0 | E30: =C30-D30 -> 0 | F30: ='January 2026'!G6 -> 0 | G30: =E30+F30 -> 0 | I30: Jul | J30: ='July 2026'!G5 -> 0 | K30: ='July 2026'!G6 -> 0 | L30: ='July 2026'!G7 -> 0 | M30: =M29+K30 -> 0
B31: Feb | C31: ='Monthly Budget'!D14 -> 0 | D31: ='February 2026'!G38 -> 0 | E31: =C31-D31 -> 0 | F31: ='February 2026'!G6 -> 0 | G31: =E31+F31 -> 0 | I31: Aug | J31: ='August 2026'!G5 -> 0 | K31: ='August 2026'!G6 -> 0 | L31: ='August 2026'!G7 -> 0 | M31: =M30+K31 -> 0
B32: Mar | C32: ='Monthly Budget'!D14 -> 0 | D32: ='March 2026'!G41 -> 0 | E32: =C32-D32 -> 0 | F32: ='March 2026'!G6 -> 0 | G32: =E32+F32 -> 0 | I32: Sep | J32: ='September 2026'!G5 -> 0 | K32: ='September 2026'!G6 -> 0 | L32: ='September 2026'!G7 -> 0 | M32: =M31+K32 -> 0
B33: Apr | C33: ='Monthly Budget'!D14 -> 0 | D33: ='April 2026'!G40 -> 0 | E33: =C33-D33 -> 0 | F33: ='April 2026'!G6 -> 0 | G33: =E33+F33 -> 0 | I33: Oct | J33: ='October 2026'!G5 -> 0 | K33: ='October 2026'!G6 -> 0 | L33: ='October 2026'!G7 -> 0 | M33: =M32+K33 -> 0
B34: May | C34: ='Monthly Budget'!D14 -> 0 | D34: ='May 2026'!G41 -> 0 | E34: =C34-D34 -> 0 | F34: ='May 2026'!G6 -> 0 | G34: =E34+F34 -> 0 | I34: Nov | J34: ='November 2026'!G5 -> 0 | K34: ='November 2026'!G6 -> 0 | L34: ='November 2026'!G7 -> 0 | M34: =M33+K34 -> 0
B35: Jun | C35: ='Monthly Budget'!D14 -> 0 | D35: ='June 2026'!G40 -> 0 | E35: =C35-D35 -> 0 | F35: ='June 2026'!G6 -> 0 | G35: =E35+F35 -> 0 | I35: Dec | J35: ='December 2026'!G5 -> 0 | K35: ='December 2026'!G6 -> 0 | L35: ='December 2026'!G7 -> 0 | M35: =M34+K35 -> 0
B36: Jul | C36: ='Monthly Budget'!D14 -> 0 | D36: ='July 2026'!G41 -> 0 | E36: =C36-D36 -> 0 | F36: ='July 2026'!G6 -> 0 | G36: =E36+F36 -> 0 | I36: TOTAL | J36: =SUM(J24:J35) -> 0 | K36: =SUM(K24:K35) -> 0 | L36: =SUM(L24:L35) -> 0 | M36: =M35 -> 0
B37: Aug | C37: ='Monthly Budget'!D14 -> 0 | D37: ='August 2026'!G41 -> 0 | E37: =C37-D37 -> 0 | F37: ='August 2026'!G6 -> 0 | G37: =E37+F37 -> 0
B38: Sep | C38: ='Monthly Budget'!D14 -> 0 | D38: ='September 2026'!G40 -> 0 | E38: =C38-D38 -> 0 | F38: ='September 2026'!G6 -> 0 | G38: =E38+F38 -> 0 | I38: CUMULATIVE BALANCE SUMMARY
B39: Oct | C39: ='Monthly Budget'!D14 -> 0 | D39: ='October 2026'!G41 -> 0 | E39: =C39-D39 -> 0 | F39: ='October 2026'!G6 -> 0 | G39: =E39+F39 -> 0 | I39: Total Salary (YTD): | L39: =J36 -> 0
B40: Nov | C40: ='Monthly Budget'!D14 -> 0 | D40: ='November 2026'!G40 -> 0 | E40: =C40-D40 -> 0 | F40: ='November 2026'!G6 -> 0 | G40: =E40+F40 -> 0 | I40: Total Freelance (YTD): | L40: =K36 -> 0
B41: Dec | C41: ='Monthly Budget'!D14 -> 0 | D41: ='December 2026'!G41 -> 0 | E41: =C41-D41 -> 0 | F41: ='December 2026'!G6 -> 0 | G41: =E41+F41 -> 0 | I41: Total Income (YTD): | L41: =L36 -> 0
B42: TOTAL | C42: =SUM(C30:C41) -> 0 | D42: =SUM(D30:D41) -> 0 | E42: =SUM(E30:E41) -> 0 | F42: =SUM(F30:F41) -> 0 | G42: =SUM(G30:G41) -> 0 | I42: Total Expenses (YTD): | L42: =D42 -> 0
I43: Net Surplus (YTD): | L43: =G42 -> 0
...

Sheet Monthly Budget
B1: MONTHLY BUDGET
B2: # | C2: Category | D2: Monthly | E2: Annual | F2: % of Total | G2: Color Code
B3: 1 | C3: Rent + Utilities | D3: 34300 | E3: =D3*12 -> 0 | F3: =IFERROR(IF($D$14>0,D3/$D$14,0),0) -> 0 | G3: Rent + Utilities
B4: 2 | C4: Electricity Deposit | D4: 2884 | E4: =D4*12 -> 0 | F4: =IFERROR(IF($D$14>0,D4/$D$14,0),0) -> 0 | G4: Electricity Deposit
B5: 3 | C5: Internet & Phone Bills | D5: 1200 | E5: =D5*12 -> 0 | F5: =IFERROR(IF($D$14>0,D5/$D$14,0),0) -> 0 | G5: Internet & Phone Bills
B6: 4 | C6: Food & Groceries | D6: 6000 | E6: =D6*12 -> 0 | F6: =IFERROR(IF($D$14>0,D6/$D$14,0),0) -> 0 | G6: Food & Groceries
B7: 5 | C7: Investments | D7: 4000 | E7: =D7*12 -> 0 | F7: =IFERROR(IF($D$14>0,D7/$D$14,0),0) -> 0 | G7: Investments
B8: 6 | C8: Date Nights | D8: 1500 | E8: =D8*12 -> 0 | F8: =IFERROR(IF($D$14>0,D8/$D$14,0),0) -> 0 | G8: Date Nights
B9: 7 | C9: Annual Costs Savings | D9: 1816 | E9: =D9*12 -> 0 | F9: =IFERROR(IF($D$14>0,D9/$D$14,0),0) -> 0 | G9: Annual Costs Savings
B10: 8 | C10: Emergency Buffer | D10: 1000 | E10: =D10*12 -> 0 | F10: =IFERROR(IF($D$14>0,D10/$D$14,0),0) -> 0 | G10: Emergency Buffer
B11: 9 | C11: Personal Care | D11: 1000 | E11: =D11*12 -> 0 | F11: =IFERROR(IF($D$14>0,D11/$D$14,0),0) -> 0 | G11: Personal Care
B12: 10 | C12: Personal Savings | D12: 4300 | E12: =D12*12 -> 0 | F12: =IFERROR(IF($D$14>0,D12/$D$14,0),0) -> 0 | G12: Personal Savings
B13: 11 | C13: Miscellaneous | D13: 2000 | E13: =D13*12 -> 0 | F13: =IFERROR(IF($D$14>0,D13/$D$14,0),0) -> 0 | G13: Miscellaneous
C14: TOTAL MONTHLY BUDGET | D14: =SUM(D3:D13) -> 0 | E14: =SUM(E3:E13) -> 0 | F14: =SUM(F3:F13) -> 0
B16: INCOME INFORMATION
C17: Combined Monthly Income | D17: 60000 | E17: =D17*12 -> 0
C18: Target Monthly Savings | D18: 5,000 - 10,000 | E18: 60,000 - 120,000
C19: Target Savings Rate | D19: 8% - 17%

Sheet January 2026
B1: JANUARY 2026 EXPENSE TRACKER
B2: January 01 - January 31, 2026 (31 days)
B4: MONTH BALANCE & INCOME | F4: INCOME TRACKING | K4: January CATEGORY BREAKDOWN
B5: Opening Balance: | C5: 0 | F5: Salary (Fixed): | G5: 60000 | H5: Currency: | I5: =Dashboard!$N$2 -> 0 | K5: Category | L5: Budget | M5: Spent | N5: Status
B6: Closing Balance: | C6: 0 | F6: Freelance Income: | G6: 0 | H6: Currency: | I6: CZK | K6: Rent + Utilities | L6: ='Monthly Budget'!D3 -> 0 | M6: =SUMIF(E:E,K6,G:G) -> 0 | N6: =IF(M6>L6,"OVER",IF(M6>L6*0.9,"WARN","OK")) -> 0
B7: Net Change: | C7: =C6-C5 -> 0 | F7: Total Income: | G7: =G5+G6 -> 0 | K7: Electricity Deposit | L7: ='Monthly Budget'!D4 -> 0 | M7: =SUMIF(E:E,K7,G:G) -> 0 | N7: =IF(M7>L7,"OVER",IF(M7>L7*0.9,"WARN","OK")) -> 0
K8: Internet & Phone Bills | L8: ='Monthly Budget'!D5 -> 0 | M8: =SUMIF(E:E,K8,G:G) -> 0 | N8: =IF(M8>L8,"OVER",IF(M8>L8*0.9,"WARN","OK")) -> 0
B9: # | C9: Date | D9: Day | E9: Category | F9: Description | G9: Amount | H9: Payment | I9: Running Total | K9: Food & Groceries | L9: ='Monthly Budget'!D6 -> 0 | M9: =SUMIF(E:E,K9,G:G) -> 0 | N9: =IF(M9>L9,"OVER",IF(M9>L9*0.9,"WARN","OK")) -> 0
B10: 1 | C10: 46023 | D10: Thu | I10: =G10 -> 0 | K10: Investments | L10: ='Monthly Budget'!D7 -> 0 | M10: =SUMIF(E:E,K10,G:G) -> 0 | N10: =IF(M10>L10,"OVER",IF(M10>L10*0.9,"WARN","OK")) -> 0
B11: 2 | C11: 46024 | D11: Fri | I11: =I10+G11 -> 0 | K11: Date Nights | L11: ='Monthly Budget'!D8 -> 0 | M11: =SUMIF(E:E,K11,G:G) -> 0 | N11: =IF(M11>L11,"OVER",IF(M11>L11*0.9,"WARN","OK")) -> 0
B12: 3 | C12: 46025 | D12: Sat | I12: =I11+G12 -> 0 | K12: Annual Costs Savings | L12: ='Monthly Budget'!D9 -> 0 | M12: =SUMIF(E:E,K12,G:G) -> 0 | N12: =IF(M12>L12,"OVER",IF(M12>L12*0.9,"WARN","OK")) -> 0
B13: 4 | C13: 46026 | D13: Sun | I13: =I12+G13 -> 0 | K13: Emergency Buffer | L13: ='Monthly Budget'!D10 -> 0 | M13: =SUMIF(E:E,K13,G:G) -> 0 | N13: =IF(M13>L13,"OVER",IF(M13>L13*0.9,"WARN","OK")) -> 0
B14: 5 | C14: 46027 | D14: Mon | I14: =I13+G14 -> 0 | K14: Personal Care | L14: ='Monthly Budget'!D11 -> 0 | M14: =SUMIF(E:E,K14,G:G) -> 0 | N14: =IF(M14>L14,"OVER",IF(M14>L14*0.9,"WARN","OK")) -> 0
B15: 6 | C15: 46028 | D15: Tue | I15: =I14+G15 -> 0 | K15: Personal Savings | L15: ='Monthly Budget'!D12 -> 0 | M15: =SUMIF(E:E,K15,G:G) -> 0 | N15: =IF(M15>L15,"OVER",IF(M15>L15*0.9,"WARN","OK")) -> 0
B16: 7 | C16: 46029 | D16: Wed | I16: =I15+G16 -> 0 | K16: Miscellaneous | L16: ='Monthly Budget'!D13 -> 0 | M16: =SUMIF(E:E,K16,G:G) -> 0 | N16: =IF(M16>L16,"OVER",IF(M16>L16*0.9,"WARN","OK")) -> 0
B17: 8 | C17: 46030 | D17: Thu | I17: =I16+G17 -> 0 | K17: TOTAL | L17: =SUM(L6:L16) -> 0 | M17: =SUM(M6:M16) -> 0
B18: 9 | C18: 46031 | D18: Fri | I18: =I17+G18 -> 0
B19: 10 | C19: 46032 | D19: Sat | I19: =I18+G19 -> 0
B20: 11 | C20: 46033 | D20: Sun | I20: =I19+G20 -> 0
B21: 12 | C21: 46034 | D21: Mon | I21: =I20+G21 -> 0
B22: 13 | C22: 46035 | D22: Tue | I22: =I21+G22 -> 0
B23: 14 | C23: 46036 | D23: Wed | I23: =I22+G23 -> 0
B24: 15 | C24: 46037 | D24: Thu | I24: =I23+G24 -> 0
B25: 16 | C25: 46038 | D25: Fri | I25: =I24+G25 -> 0
B26: 17 | C26: 46039 | D26: Sat | I26: =I25+G26 -> 0
B27: 18 | C27: 46040 | D27: Sun | I27: =I26+G27 -> 0
B28: 19 | C28: 46041 | D28: Mon | I28: =I27+G28 -> 0
B29: 20 | C29: 46042 | D29: Tue | I29: =I28+G29 -> 0
... B40: 31 | C40: 46053 | D40: Sat | I40: =I39+G40 -> 0
F41: MONTH TOTAL: | G41: =SUM(G10:G40) -> 0

Sheet February 2026
B1: FEBRUARY 2026 EXPENSE TRACKER
B2: February 01 - February 28, 2026 (28 days)
B4: MONTH BALANCE & INCOME | F4: INCOME TRACKING | K4: February CATEGORY BREAKDOWN
B5: Opening Balance: | C5: 0 | F5: Salary (Fixed): | G5: 60000 | H5: Currency: | I5: =Dashboard!$N$2 -> 0 | K5: Category | L5: Budget | M5: Spent | N5: Status
B6: Closing Balance: | C6: 0 | F6: Freelance Income: | G6: 0 | H6: Currency: | I6: CZK | K6: Rent + Utilities | L6: ='Monthly Budget'!D3 -> 0 | M6: =SUMIF(E:E,K6,G:G) -> 0 | N6: =IF(M6>L6,"OVER",IF(M6>L6*0.9,"WARN","OK")) -> 0
B7: Net Change: | C7: =C6-C5 -> 0 | F7: Total Income: | G7: =G5+G6 -> 0 | K7: Electricity Deposit | L7: ='Monthly Budget'!D4 -> 0 | M7: =SUMIF(E:E,K7,G:G) -> 0 | N7: =IF(M7>L7,"OVER",IF(M7>L7*0.9,"WARN","OK")) -> 0
K8: Internet & Phone Bills | L8: ='Monthly Budget'!D5 -> 0 | M8: =SUMIF(E:E,K8,G:G) -> 0 | N8: =IF(M8>L8,"OVER",IF(M8>L8*0.9,"WARN","OK")) -> 0
B9: # | C9: Date | D9: Day | E9: Category | F9: Description | G9: Amount | H9: Payment | I9: Running Total | K9: Food & Groceries | L9: ='Monthly Budget'!D6 -> 0 | M9: =SUMIF(E:E,K9,G:G) -> 0 | N9: =IF(M9>L9,"OVER",IF(M9>L9*0.9,"WARN","OK")) -> 0
B10: 1 | C10: 46054 | D10: Sun | I10: =G10 -> 0 | K10: Investments | L10: ='Monthly Budget'!D7 -> 0 | M10: =SUMIF(E:E,K10,G:G) -> 0 | N10: =IF(M10>L10,"OVER",IF(M10>L10*0.9,"WARN","OK")) -> 0
B11: 2 | C11: 46055 | D11: Mon | I11: =I10+G11 -> 0 | K11: Date Nights | L11: ='Monthly Budget'!D8 -> 0 | M11: =SUMIF(E:E,K11,G:G) -> 0 | N11: =IF(M11>L11,"OVER",IF(M11>L11*0.9,"WARN","OK")) -> 0
B12: 3 | C12: 46056 | D12: Tue | I12: =I11+G12 -> 0 | K12: Annual Costs Savings | L12: ='Monthly Budget'!D9 -> 0 | M12: =SUMIF(E:E,K12,G:G) -> 0 | N12: =IF(M12>L12,"OVER",IF(M12>L12*0.9,"WARN","OK")) -> 0
B13: 4 | C13: 46057 | D13: Wed | I13: =I12+G13 -> 0 | K13: Emergency Buffer | L13: ='Monthly Budget'!D10 -> 0 | M13: =SUMIF(E:E,K13,G:G) -> 0 | N13: =IF(M13>L13,"OVER",IF(M13>L13*0.9,"WARN","OK")) -> 0
B14: 5 | C14: 46058 | D14: Thu | I14: =I13+G14 -> 0 | K14: Personal Care | L14: ='Monthly Budget'!D11 -> 0 | M14: =SUMIF(E:E,K14,G:G) -> 0 | N14: =IF(M14>L14,"OVER",IF(M14>L14*0.9,"WARN","OK")) -> 0
B15: 6 | C15: 46059 | D15: Fri | I15: =I14+G15 -> 0 | K15: Personal Savings | L15: ='Monthly Budget'!D12 -> 0 | M15: =SUMIF(E:E,K15,G:G) -> 0 | N15: =IF(M15>L15,"OVER",IF(M15>L15*0.9,"WARN","OK")) -> 0
B16: 7 | C16: 46060 | D16: Sat | I16: =I15+G16 -> 0 | K16: Miscellaneous | L16: ='Monthly Budget'!D13 -> 0 | M16: =SUMIF(E:E,K16,G:G) -> 0 | N16: =IF(M16>L16,"OVER",IF(M16>L16*0.9,"WARN","OK")) -> 0
B17: 8 | C17: 46061 | D17: Sun | I17: =I16+G17 -> 0 | K17: TOTAL | L17: =SUM(L6:L16) -> 0 | M17: =SUM(M6:M16) -> 0
B18: 9 | C18: 46062 | D18: Mon | I18: =I17+G18 -> 0
B19: 10 | C19: 46063 | D19: Tue | I19: =I18+G19 -> 0
B20: 11 | C20: 46064 | D20: Wed | I20: =I19+G20 -> 0
B21: 12 | C21: 46065 | D21: Thu | I21: =I20+G21 -> 0
B22: 13 | C22: 46066 | D22: Fri | I22: =I21+G22 -> 0
B23: 14 | C23: 46067 | D23: Sat | I23: =I22+G23 -> 0
B24: 15 | C24: 46068 | D24: Sun | I24: =I23+G24 -> 0
B25: 16 | C25: 46069 | D25: Mon | I25: =I24+G25 -> 0
B26: 17 | C26: 46070 | D26: Tue | I26: =I25+G26 -> 0
B27: 18 | C27: 46071 | D27: Wed | I27: =I26+G27 -> 0
B28: 19 | C28: 46072 | D28: Thu | I28: =I27+G28 -> 0
B29: 20 | C29: 46073 | D29: Fri | I29: =I28+G29 -> 0
... B37: 28 | C37: 46081 | D37: Sat | I37: =I36+G37 -> 0
F38: MONTH TOTAL: | G38: =SUM(G10:G37) -> 0

Sheet March 2026
B1: MARCH 2026 EXPENSE TRACKER
B2: March 01 - March 31, 2026 (31 days)
B4: MONTH BALANCE & INCOME | F4: INCOME TRACKING | K4: March CATEGORY BREAKDOWN
B5: Opening Balance: | C5: 0 | F5: Salary (Fixed): | G5: 60000 | H5: Currency: | I5: =Dashboard!$N$2 -> 0 | K5: Category | L5: Budget | M5: Spent | N5: Status
B6: Closing Balance: | C6: 0 | F6: Freelance Income: | G6: 0 | H6: Currency: | I6: CZK | K6: Rent + Utilities | L6: ='Monthly Budget'!D3 -> 0 | M6: =SUMIF(E:E,K6,G:G) -> 0 | N6: =IF(M6>L6,"OVER",IF(M6>L6*0.9,"WARN","OK")) -> 0
B7: Net Change: | C7: =C6-C5 -> 0 | F7: Total Income: | G7: =G5+G6 -> 0 | K7: Electricity Deposit | L7: ='Monthly Budget'!D4 -> 0 | M7: =SUMIF(E:E,K7,G:G) -> 0 | N7: =IF(M7>L7,"OVER",IF(M7>L7*0.9,"WARN","OK")) -> 0
K8: Internet & Phone Bills | L8: ='Monthly Budget'!D5 -> 0 | M8: =SUMIF(E:E,K8,G:G) -> 0 | N8: =IF(M8>L8,"OVER",IF(M8>L8*0.9,"WARN","OK")) -> 0
B9: # | C9: Date | D9: Day | E9: Category | F9: Description | G9: Amount | H9: Payment | I9: Running Total | K9: Food & Groceries | L9: ='Monthly Budget'!D6 -> 0 | M9: =SUMIF(E:E,K9,G:G) -> 0 | N9: =IF(M9>L9,"OVER",IF(M9>L9*0.9,"WARN","OK")) -> 0
B10: 1 | C10: 46082 | D10: Sun | I10: =G10 -> 0 | K10: Investments | L10: ='Monthly Budget'!D7 -> 0 | M10: =SUMIF(E:E,K10,G:G) -> 0 | N10: =IF(M10>L10,"OVER",IF(M10>L10*0.9,"WARN","OK")) -> 0
B11: 2 | C11: 46083 | D11: Mon | I11: =I10+G11 -> 0 | K11: Date Nights | L11: ='Monthly Budget'!D8 -> 0 | M11: =SUMIF(E:E,K11,G:G) -> 0 | N11: =IF(M11>L11,"OVER",IF(M11>L11*0.9,"WARN","OK")) -> 0
B12: 3 | C12: 46084 | D12: Tue | I12: =I11+G12 -> 0 | K12: Annual Costs Savings | L12: ='Monthly Budget'!D9 -> 0 | M12: =SUMIF(E:E,K12,G:G) -> 0 | N12: =IF(M12>L12,"OVER",IF(M12>L12*0.9,"WARN","OK")) -> 0
B13: 4 | C13: 46085 | D13: Wed | I13: =I12+G13 -> 0 | K13: Emergency Buffer | L13: ='Monthly Budget'!D10 -> 0 | M13: =SUMIF(E:E,K13,G:G) -> 0 | N13: =IF(M13>L13,"OVER",IF(M13>L13*0.9,"WARN","OK")) -> 0
B14: 5 | C14: 46086 | D14: Thu | I14: =I13+G14 -> 0 | K14: Personal Care | L14: ='Monthly Budget'!D11 -> 0 | M14: =SUMIF(E:E,K14,G:G) -> 0 | N14: =IF(M14>L14,"OVER",IF(M14>L14*0.9,"WARN","OK")) -> 0
B15: 6 | C15: 46087 | D15: Fri | I15: =I14+G15 -> 0 | K15: Personal Savings | L15: ='Monthly Budget'!D12 -> 0 | M15: =SUMIF(E:E,K15,G:G) -> 0 | N15: =IF(M15>L15,"OVER",IF(M15>L15*0.9,"WARN","OK")) -> 0
B16: 7 | C16: 46088 | D16: Sat | I16: =I15+G16 -> 0 | K16: Miscellaneous | L16: ='Monthly Budget'!D13 -> 0 | M16: =SUMIF(E:E,K16,G:G) -> 0 | N16: =IF(M16>L16,"OVER",IF(M16>L16*0.9,"WARN","OK")) -> 0
B17: 8 | C17: 46089 | D17: Sun | I17: =I16+G17 -> 0 | K17: TOTAL | L17: =SUM(L6:L16) -> 0 | M17: =SUM(M6:M16) -> 0
B18: 9 | C18: 46090 | D18: Mon | I18: =I17+G18 -> 0
B19: 10 | C19: 46091 | D19: Tue | I19: =I18+G19 -> 0
B20: 11 | C20: 46092 | D20: Wed | I20: =I19+G20 -> 0
B21: 12 | C21: 46093 | D21: Thu | I21: =I20+G21 -> 0
B22: 13 | C22: 46094 | D22: Fri | I22: =I21+G22 -> 0
B23: 14 | C23: 46095 | D23: Sat | I23: =I22+G23 -> 0
B24: 15 | C24: 46096 | D24: Sun | I24: =I23+G24 -> 0
B25: 16 | C25: 46097 | D25: Mon | I25: =I24+G25 -> 0
B26: 17 | C26: 46098 | D26: Tue | I26: =I25+G26 -> 0
B27: 18 | C27: 46099 | D27: Wed | I27: =I26+G27 -> 0
B28: 19 | C28: 46100 | D28: Thu | I28: =I27+G28 -> 0
B29: 20 | C29: 46101 | D29: Fri | I29: =I28+G29 -> 0
... B40: 31 | C40: 46112 | D40: Tue | I40: =I39+G40 -> 0
F41: MONTH TOTAL: | G41: =SUM(G10:G40) -> 0

Sheet April 2026
B1: APRIL 2026 EXPENSE TRACKER
B2: April 01 - April 30, 2026 (30 days)
B4: MONTH BALANCE & INCOME | F4: INCOME TRACKING | K4: April CATEGORY BREAKDOWN
B5: Opening Balance: | C5: 0 | F5: Salary (Fixed): | G5: 60000 | H5: Currency: | I5: =Dashboard!$N$2 -> 0 | K5: Category | L5: Budget | M5: Spent | N5: Status
B6: Closing Balance: | C6: 0 | F6: Freelance Income: | G6: 0 | H6: Currency: | I6: CZK | K6: Rent + Utilities | L6: ='Monthly Budget'!D3 -> 0 | M6: =SUMIF(E:E,K6,G:G) -> 0 | N6: =IF(M6>L6,"OVER",IF(M6>L6*0.9,"WARN","OK")) -> 0
B7: Net Change: | C7: =C6-C5 -> 0 | F7: Total Income: | G7: =G5+G6 -> 0 | K7: Electricity Deposit | L7: ='Monthly Budget'!D4 -> 0 | M7: =SUMIF(E:E,K7,G:G) -> 0 | N7: =IF(M7>L7,"OVER",IF(M7>L7*0.9,"WARN","OK")) -> 0
K8: Internet & Phone Bills | L8: ='Monthly Budget'!D5 -> 0 | M8: =SUMIF(E:E,K8,G:G) -> 0 | N8: =IF(M8>L8,"OVER",IF(M8>L8*0.9,"WARN","OK")) -> 0
B9: # | C9: Date | D9: Day | E9: Category | F9: Description | G9: Amount | H9: Payment | I9: Running Total | K9: Food & Groceries | L9: ='Monthly Budget'!D6 -> 0 | M9: =SUMIF(E:E,K9,G:G) -> 0 | N9: =IF(M9>L9,"OVER",IF(M9>L9*0.9,"WARN","OK")) -> 0
B10: 1 | C10: 46113 | D10: Wed | I10: =G10 -> 0 | K10: Investments | L10: ='Monthly Budget'!D7 -> 0 | M10: =SUMIF(E:E,K10,G:G) -> 0 | N10: =IF(M10>L10,"OVER",IF(M10>L10*0.9,"WARN","OK")) -> 0
B11: 2 | C11: 46114 | D11: Thu | I11: =I10+G11 -> 0 | K11: Date Nights | L11: ='Monthly Budget'!D8 -> 0 | M11: =SUMIF(E:E,K11,G:G) -> 0 | N11: =IF(M11>L11,"OVER",IF(M11>L11*0.9,"WARN","OK")) -> 0
B12: 3 | C12: 46115 | D12: Fri | I12: =I11+G12 -> 0 | K12: Annual Costs Savings | L12: ='Monthly Budget'!D9 -> 0 | M12: =SUMIF(E:E,K12,G:G) -> 0 | N12: =IF(M12>L12,"OVER",IF(M12>L12*0.9,"WARN","OK")) -> 0
B13: 4 | C13: 46116 | D13: Sat | I13: =I12+G13 -> 0 | K13: Emergency Buffer | L13: ='Monthly Budget'!D10 -> 0 | M13: =SUMIF(E:E,K13,G:G) -> 0 | N13: =IF(M13>L13,"OVER",IF(M13>L13*0.9,"WARN","OK")) -> 0
B14: 5 | C14: 46117 | D14: Sun | I14: =I13+G14 -> 0 | K14: Personal Care | L14: ='Monthly Budget'!D11 -> 0 | M14: =SUMIF(E:E,K14,G:G) -> 0 | N14: =IF(M14>L14,"OVER",IF(M14>L14*0.9,"WARN","OK")) -> 0
B15: 6 | C15: 46118 | D15: Mon | I15: =I14+G15 -> 0 | K15: Personal Savings | L15: ='Monthly Budget'!D12 -> 0 | M15: =SUMIF(E:E,K15,G:G) -> 0 | N15: =IF(M15>L15,"OVER",IF(M15>L15*0.9,"WARN","OK")) -> 0
B16: 7 | C16: 46119 | D16: Tue | I16: =I15+G16 -> 0 | K16: Miscellaneous | L16: ='Monthly Budget'!D13 -> 0 | M16: =SUMIF(E:E,K16,G:G) -> 0 | N16: =IF(M16>L16,"OVER",IF(M16>L16*0.9,"WARN","OK")) -> 0
B17: 8 | C17: 46120 | D17: Wed | I17: =I16+G17 -> 0 | K17: TOTAL | L17: =SUM(L6:L16) -> 0 | M17: =SUM(M6:M16) -> 0
B18: 9 | C18: 46121 | D18: Thu | I18: =I17+G18 -> 0
B19: 10 | C19: 46122 | D19: Fri | I19: =I18+G19 -> 0
B20: 11 | C20: 46123 | D20: Sat | I20: =I19+G20 -> 0
B21: 12 | C21: 46124 | D21: Sun | I21: =I20+G21 -> 0
B22: 13 | C22: 46125 | D22: Mon | I22: =I21+G22 -> 0
B23: 14 | C23: 46126 | D23: Tue | I23: =I22+G23 -> 0
B24: 15 | C24: 46127 | D24: Wed | I24: =I23+G24 -> 0
B25: 16 | C25: 46128 | D25: Thu | I25: =I24+G25 -> 0
B26: 17 | C26: 46129 | D26: Fri | I26: =I25+G26 -> 0
B27: 18 | C27: 46130 | D27: Sat | I27: =I26+G27 -> 0
B28: 19 | C28: 46131 | D28: Sun | I28: =I27+G28 -> 0
B29: 20 | C29: 46132 | D29: Mon | I29: =I28+G29 -> 0
... B39: 30 | C39: 46142 | D39: Thu | I39: =I38+G39 -> 0
F40: MONTH TOTAL: | G40: =SUM(G10:G39) -> 0

Sheet May 2026
B1: MAY 2026 EXPENSE TRACKER
B2: May 01 - May 31, 2026 (31 days)
B4: MONTH BALANCE & INCOME | F4: INCOME TRACKING | K4: May CATEGORY BREAKDOWN
B5: Opening Balance: | C5: 0 | F5: Salary (Fixed): | G5: 60000 | H5: Currency: | I5: =Dashboard!$N$2 -> 0 | K5: Category | L5: Budget | M5: Spent | N5: Status
B6: Closing Balance: | C6: 0 | F6: Freelance Income: | G6: 0 | H6: Currency: | I6: CZK | K6: Rent + Utilities | L6: ='Monthly Budget'!D3 -> 0 | M6: =SUMIF(E:E,K6,G:G) -> 0 | N6: =IF(M6>L6,"OVER",IF(M6>L6*0.9,"WARN","OK")) -> 0
B7: Net Change: | C7: =C6-C5 -> 0 | F7: Total Income: | G7: =G5+G6 -> 0 | K7: Electricity Deposit | L7: ='Monthly Budget'!D4 -> 0 | M7: =SUMIF(E:E,K7,G:G) -> 0 | N7: =IF(M7>L7,"OVER",IF(M7>L7*0.9,"WARN","OK")) -> 0
K8: Internet & Phone Bills | L8: ='Monthly Budget'!D5 -> 0 | M8: =SUMIF(E:E,K8,G:G) -> 0 | N8: =IF(M8>L8,"OVER",IF(M8>L8*0.9,"WARN","OK")) -> 0
B9: # | C9: Date | D9: Day | E9: Category | F9: Description | G9: Amount | H9: Payment | I9: Running Total | K9: Food & Groceries | L9: ='Monthly Budget'!D6 -> 0 | M9: =SUMIF(E:E,K9,G:G) -> 0 | N9: =IF(M9>L9,"OVER",IF(M9>L9*0.9,"WARN","OK")) -> 0
B10: 1 | C10: 46143 | D10: Fri | I10: =G10 -> 0 | K10: Investments | L10: ='Monthly Budget'!D7 -> 0 | M10: =SUMIF(E:E,K10,G:G) -> 0 | N10: =IF(M10>L10,"OVER",IF(M10>L10*0.9,"WARN","OK")) -> 0
B11: 2 | C11: 46144 | D11: Sat | I11: =I10+G11 -> 0 | K11: Date Nights | L11: ='Monthly Budget'!D8 -> 0 | M11: =SUMIF(E:E,K11,G:G) -> 0 | N11: =IF(M11>L11,"OVER",IF(M11>L11*0.9,"WARN","OK")) -> 0
B12: 3 | C12: 46145 | D12: Sun | I12: =I11+G12 -> 0 | K12: Annual Costs Savings | L12: ='Monthly Budget'!D9 -> 0 | M12: =SUMIF(E:E,K12,G:G) -> 0 | N12: =IF(M12>L12,"OVER",IF(M12>L12*0.9,"WARN","OK")) -> 0
B13: 4 | C13: 46146 | D13: Mon | I13: =I12+G13 -> 0 | K13: Emergency Buffer | L13: ='Monthly Budget'!D10 -> 0 | M13: =SUMIF(E:E,K13,G:G) -> 0 | N13: =IF(M13>L13,"OVER",IF(M13>L13*0.9,"WARN","OK")) -> 0
B14: 5 | C14: 46147 | D14: Tue | I14: =I13+G14 -> 0 | K14: Personal Care | L14: ='Monthly Budget'!D11 -> 0 | M14: =SUMIF(E:E,K14,G:G) -> 0 | N14: =IF(M14>L14,"OVER",IF(M14>L14*0.9,"WARN","OK")) -> 0
B15: 6 | C15: 46148 | D15: Wed | I15: =I14+G15 -> 0 | K15: Personal Savings | L15: ='Monthly Budget'!D12 -> 0 | M15: =SUMIF(E:E,K15,G:G) -> 0 | N15: =IF(M15>L15,"OVER",IF(M15>L15*0.9,"WARN","OK")) -> 0
B16: 7 | C16: 46149 | D16: Thu | I16: =I15+G16 -> 0 | K16: Miscellaneous | L16: ='Monthly Budget'!D13 -> 0 | M16: =SUMIF(E:E,K16,G:G) -> 0 | N16: =IF(M16>L16,"OVER",IF(M16>L16*0.9,"WARN","OK")) -> 0
B17: 8 | C17: 46150 | D17: Fri | I17: =I16+G17 -> 0 | K17: TOTAL | L17: =SUM(L6:L16) -> 0 | M17: =SUM(M6:M16) -> 0
B18: 9 | C18: 46151 | D18: Sat | I18: =I17+G18 -> 0
B19: 10 | C19: 46152 | D19: Sun | I19: =I18+G19 -> 0
B20: 11 | C20: 46153 | D20: Mon | I20: =I19+G20 -> 0
B21: 12 | C21: 46154 | D21: Tue | I21: =I20+G21 -> 0
B22: 13 | C22: 46155 | D22: Wed | I22: =I21+G22 -> 0
B23: 14 | C23: 46156 | D23: Thu | I23: =I22+G23 -> 0
B24: 15 | C24: 46157 | D24: Fri | I24: =I23+G24 -> 0
B25: 16 | C25: 46158 | D25: Sat | I25: =I24+G25 -> 0
B26: 17 | C26: 46159 | D26: Sun | I26: =I25+G26 -> 0
B27: 18 | C27: 46160 | D27: Mon | I27: =I26+G27 -> 0
B28: 19 | C28: 46161 | D28: Tue | I28: =I27+G28 -> 0
B29: 20 | C29: 46162 | D29: Wed | I29: =I28+G29 -> 0
... B40: 31 | C40: 46173 | D40: Sun | I40: =I39+G40 -> 0
F41: MONTH TOTAL: | G41: =SUM(G10:G40) -> 0

Sheet June 2026
B1: JUNE 2026 EXPENSE TRACKER
B2: June 01 - June 30, 2026 (30 days)
B4: MONTH BALANCE & INCOME | F4: INCOME TRACKING | K4: June CATEGORY BREAKDOWN
B5: Opening Balance: | C5: 0 | F5: Salary (Fixed): | G5: 60000 | H5: Currency: | I5: =Dashboard!$N$2 -> 0 | K5: Category | L5: Budget | M5: Spent | N5: Status
B6: Closing Balance: | C6: 0 | F6: Freelance Income: | G6: 0 | H6: Currency: | I6: CZK | K6: Rent + Utilities | L6: ='Monthly Budget'!D3 -> 0 | M6: =SUMIF(E:E,K6,G:G) -> 0 | N6: =IF(M6>L6,"OVER",IF(M6>L6*0.9,"WARN","OK")) -> 0
B7: Net Change: | C7: =C6-C5 -> 0 | F7: Total Income: | G7: =G5+G6 -> 0 | K7: Electricity Deposit | L7: ='Monthly Budget'!D4 -> 0 | M7: =SUMIF(E:E,K7,G:G) -> 0 | N7: =IF(M7>L7,"OVER",IF(M7>L7*0.9,"WARN","OK")) -> 0
K8: Internet & Phone Bills | L8: ='Monthly Budget'!D5 -> 0 | M8: =SUMIF(E:E,K8,G:G) -> 0 | N8: =IF(M8>L8,"OVER",IF(M8>L8*0.9,"WARN","OK")) -> 0
B9: # | C9: Date | D9: Day | E9: Category | F9: Description | G9: Amount | H9: Payment | I9: Running Total | K9: Food & Groceries | L9: ='Monthly Budget'!D6 -> 0 | M9: =SUMIF(E:E,K9,G:G) -> 0 | N9: =IF(M9>L9,"OVER",IF(M9>L9*0.9,"WARN","OK")) -> 0
B10: 1 | C10: 46174 | D10: Mon | I10: =G10 -> 0 | K10: Investments | L10: ='Monthly Budget'!D7 -> 0 | M10: =SUMIF(E:E,K10,G:G) -> 0 | N10: =IF(M10>L10,"OVER",IF(M10>L10*0.9,"WARN","OK")) -> 0
B11: 2 | C11: 46175 | D11: Tue | I11: =I10+G11 -> 0 | K11: Date Nights | L11: ='Monthly Budget'!D8 -> 0 | M11: =SUMIF(E:E,K11,G:G) -> 0 | N11: =IF(M11>L11,"OVER",IF(M11>L11*0.9,"WARN","OK")) -> 0
B12: 3 | C12: 46176 | D12: Wed | I12: =I11+G12 -> 0 | K12: Annual Costs Savings | L12: ='Monthly Budget'!D9 -> 0 | M12: =SUMIF(E:E,K12,G:G) -> 0 | N12: =IF(M12>L12,"OVER",IF(M12>L12*0.9,"WARN","OK")) -> 0
B13: 4 | C13: 46177 | D13: Thu | I13: =I12+G13 -> 0 | K13: Emergency Buffer | L13: ='Monthly Budget'!D10 -> 0 | M13: =SUMIF(E:E,K13,G:G) -> 0 | N13: =IF(M13>L13,"OVER",IF(M13>L13*0.9,"WARN","OK")) -> 0
B14: 5 | C14: 46178 | D14: Fri | I14: =I13+G14 -> 0 | K14: Personal Care | L14: ='Monthly Budget'!D11 -> 0 | M14: =SUMIF(E:E,K14,G:G) -> 0 | N14: =IF(M14>L14,"OVER",IF(M14>L14*0.9,"WARN","OK")) -> 0
B15: 6 | C15: 46179 | D15: Sat | I15: =I14+G15 -> 0 | K15: Personal Savings | L15: ='Monthly Budget'!D12 -> 0 | M15: =SUMIF(E:E,K15,G:G) -> 0 | N15: =IF(M15>L15,"OVER",IF(M15>L15*0.9,"WARN","OK")) -> 0
B16: 7 | C16: 46180 | D16: Sun | I16: =I15+G16 -> 0 | K16: Miscellaneous | L16: ='Monthly Budget'!D13 -> 0 | M16: =SUMIF(E:E,K16,G:G) -> 0 | N16: =IF(M16>L16,"OVER",IF(M16>L16*0.9,"WARN","OK")) -> 0
B17: 8 | C17: 46181 | D17: Mon | I17: =I16+G17 -> 0 | K17: TOTAL | L17: =SUM(L6:L16) -> 0 | M17: =SUM(M6:M16) -> 0
B18: 9 | C18: 46182 | D18: Tue | I18: =I17+G18 -> 0
B19: 10 | C19: 46183 | D19: Wed | I19: =I18+G19 -> 0
B20: 11 | C20: 46184 | D20: Thu | I20: =I19+G20 -> 0
B21: 12 | C21: 46185 | D21: Fri | I21: =I20+G21 -> 0
B22: 13 | C22: 46186 | D22: Sat | I22: =I21+G22 -> 0
B23: 14 | C23: 46187 | D23: Sun | I23: =I22+G23 -> 0
B24: 15 | C24: 46188 | D24: Mon | I24: =I23+G24 -> 0
B25: 16 | C25: 46189 | D25: Tue | I25: =I24+G25 -> 0
B26: 17 | C26: 46190 | D26: Wed | I26: =I25+G26 -> 0
B27: 18 | C27: 46191 | D27: Thu | I27: =I26+G27 -> 0
B28: 19 | C28: 46192 | D28: Fri | I28: =I27+G28 -> 0
B29: 20 | C29: 46193 | D29: Sat | I29: =I28+G29 -> 0
... B39: 30 | C39: 46203 | D39: Tue | I39: =I38+G39 -> 0
F40: MONTH TOTAL: | G40: =SUM(G10:G39) -> 0

Sheet July 2026
B1: JULY 2026 EXPENSE TRACKER
B2: July 01 - July 31, 2026 (31 days)
B4: MONTH BALANCE & INCOME | F4: INCOME TRACKING | K4: July CATEGORY BREAKDOWN
B5: Opening Balance: | C5: 0 | F5: Salary (Fixed): | G5: 60000 | H5: Currency: | I5: =Dashboard!$N$2 -> 0 | K5: Category | L5: Budget | M5: Spent | N5: Status
B6: Closing Balance: | C6: 0 | F6: Freelance Income: | G6: 0 | H6: Currency: | I6: CZK | K6: Rent + Utilities | L6: ='Monthly Budget'!D3 -> 0 | M6: =SUMIF(E:E,K6,G:G) -> 0 | N6: =IF(M6>L6,"OVER",IF(M6>L6*0.9,"WARN","OK")) -> 0
B7: Net Change: | C7: =C6-C5 -> 0 | F7: Total Income: | G7: =G5+G6 -> 0 | K7: Electricity Deposit | L7: ='Monthly Budget'!D4 -> 0 | M7: =SUMIF(E:E,K7,G:G) -> 0 | N7: =IF(M7>L7,"OVER",IF(M7>L7*0.9,"WARN","OK")) -> 0
K8: Internet & Phone Bills | L8: ='Monthly Budget'!D5 -> 0 | M8: =SUMIF(E:E,K8,G:G) -> 0 | N8: =IF(M8>L8,"OVER",IF(M8>L8*0.9,"WARN","OK")) -> 0
B9: # | C9: Date | D9: Day | E9: Category | F9: Description | G9: Amount | H9: Payment | I9: Running Total | K9: Food & Groceries | L9: ='Monthly Budget'!D6 -> 0 | M9: =SUMIF(E:E,K9,G:G) -> 0 | N9: =IF(M9>L9,"OVER",IF(M9>L9*0.9,"WARN","OK")) -> 0
B10: 1 | C10: 46204 | D10: Wed | I10: =G10 -> 0 | K10: Investments | L10: ='Monthly Budget'!D7 -> 0 | M10: =SUMIF(E:E,K10,G:G) -> 0 | N10: =IF(M10>L10,"OVER",IF(M10>L10*0.9,"WARN","OK")) -> 0
B11: 2 | C11: 46205 | D11: Thu | I11: =I10+G11 -> 0 | K11: Date Nights | L11: ='Monthly Budget'!D8 -> 0 | M11: =SUMIF(E:E,K11,G:G) -> 0 | N11: =IF(M11>L11,"OVER",IF(M11>L11*0.9,"WARN","OK")) -> 0
B12: 3 | C12: 46206 | D12: Fri | I12: =I11+G12 -> 0 | K12: Annual Costs Savings | L12: ='Monthly Budget'!D9 -> 0 | M12: =SUMIF(E:E,K12,G:G) -> 0 | N12: =IF(M12>L12,"OVER",IF(M12>L12*0.9,"WARN","OK")) -> 0
B13: 4 | C13: 46207 | D13: Sat | I13: =I12+G13 -> 0 | K13: Emergency Buffer | L13: ='Monthly Budget'!D10 -> 0 | M13: =SUMIF(E:E,K13,G:G) -> 0 | N13: =IF(M13>L13,"OVER",IF(M13>L13*0.9,"WARN","OK")) -> 0
B14: 5 | C14: 46208 | D14: Sun | I14: =I13+G14 -> 0 | K14: Personal Care | L14: ='Monthly Budget'!D11 -> 0 | M14: =SUMIF(E:E,K14,G:G) -> 0 | N14: =IF(M14>L14,"OVER",IF(M14>L14*0.9,"WARN","OK")) -> 0
B15: 6 | C15: 46209 | D15: Mon | I15: =I14+G15 -> 0 | K15: Personal Savings | L15: ='Monthly Budget'!D12 -> 0 | M15: =SUMIF(E:E,K15,G:G) -> 0 | N15: =IF(M15>L15,"OVER",IF(M15>L15*0.9,"WARN","OK")) -> 0
B16: 7 | C16: 46210 | D16: Tue | I16: =I15+G16 -> 0 | K16: Miscellaneous | L16: ='Monthly Budget'!D13 -> 0 | M16: =SUMIF(E:E,K16,G:G) -> 0 | N16: =IF(M16>L16,"OVER",IF(M16>L16*0.9,"WARN","OK")) -> 0
B17: 8 | C17: 46211 | D17: Wed | I17: =I16+G17 -> 0 | K17: TOTAL | L17: =SUM(L6:L16) -> 0 | M17: =SUM(M6:M16) -> 0
B18: 9 | C18: 46212 | D18: Thu | I18: =I17+G18 -> 0
B19: 10 | C19: 46213 | D19: Fri | I19: =I18+G19 -> 0
B20: 11 | C20: 46214 | D20: Sat | I20: =I19+G20 -> 0
B21: 12 | C21: 46215 | D21: Sun | I21: =I20+G21 -> 0
B22: 13 | C22: 46216 | D22: Mon | I22: =I21+G22 -> 0
B23: 14 | C23: 46217 | D23: Tue | I23: =I22+G23 -> 0
B24: 15 | C24: 46218 | D24: Wed | I24: =I23+G24 -> 0
B25: 16 | C25: 46219 | D25: Thu | I25: =I24+G25 -> 0
B26: 17 | C26: 46220 | D26: Fri | I26: =I25+G26 -> 0
B27: 18 | C27: 46221 | D27: Sat | I27: =I26+G27 -> 0
B28: 19 | C28: 46222 | D28: Sun | I28: =I27+G28 -> 0
B29: 20 | C29: 46223 | D29: Mon | I29: =I28+G29 -> 0
... B40: 31 | C40: 46234 | D40: Fri | I40: =I39+G40 -> 0
F41: MONTH TOTAL: | G41: =SUM(G10:G40) -> 0

Sheet August 2026
B1: AUGUST 2026 EXPENSE TRACKER
B2: August 01 - August 31, 2026 (31 days)
B4: MONTH BALANCE & INCOME | F4: INCOME TRACKING | K4: August CATEGORY BREAKDOWN
B5: Opening Balance: | C5: 0 | F5: Salary (Fixed): | G5: 60000 | H5: Currency: | I5: =Dashboard!$N$2 -> 0 | K5: Category | L5: Budget | M5: Spent | N5: Status
B6: Closing Balance: | C6: 0 | F6: Freelance Income: | G6: 0 | H6: Currency: | I6: CZK | K6: Rent + Utilities | L6: ='Monthly Budget'!D3 -> 0 | M6: =SUMIF(E:E,K6,G:G) -> 0 | N6: =IF(M6>L6,"OVER",IF(M6>L6*0.9,"WARN","OK")) -> 0
B7: Net Change: | C7: =C6-C5 -> 0 | F7: Total Income: | G7: =G5+G6 -> 0 | K7: Electricity Deposit | L7: ='Monthly Budget'!D4 -> 0 | M7: =SUMIF(E:E,K7,G:G) -> 0 | N7: =IF(M7>L7,"OVER",IF(M7>L7*0.9,"WARN","OK")) -> 0
K8: Internet & Phone Bills | L8: ='Monthly Budget'!D5 -> 0 | M8: =SUMIF(E:E,K8,G:G) -> 0 | N8: =IF(M8>L8,"OVER",IF(M8>L8*0.9,"WARN","OK")) -> 0
B9: # | C9: Date | D9: Day | E9: Category | F9: Description | G9: Amount | H9: Payment | I9: Running Total | K9: Food & Groceries | L9: ='Monthly Budget'!D6 -> 0 | M9: =SUMIF(E:E,K9,G:G) -> 0 | N9: =IF(M9>L9,"OVER",IF(M9>L9*0.9,"WARN","OK")) -> 0
B10: 1 | C10: 46235 | D10: Sat | I10: =G10 -> 0 | K10: Investments | L10: ='Monthly Budget'!D7 -> 0 | M10: =SUMIF(E:E,K10,G:G) -> 0 | N10: =IF(M10>L10,"OVER",IF(M10>L10*0.9,"WARN","OK")) -> 0
B11: 2 | C11: 46236 | D11: Sun | I11: =I10+G11 -> 0 | K11: Date Nights | L11: ='Monthly Budget'!D8 -> 0 | M11: =SUMIF(E:E,K11,G:G) -> 0 | N11: =IF(M11>L11,"OVER",IF(M11>L11*0.9,"WARN","OK")) -> 0
B12: 3 | C12: 46237 | D12: Mon | I12: =I11+G12 -> 0 | K12: Annual Costs Savings | L12: ='Monthly Budget'!D9 -> 0 | M12: =SUMIF(E:E,K12,G:G) -> 0 | N12: =IF(M12>L12,"OVER",IF(M12>L12*0.9,"WARN","OK")) -> 0
B13: 4 | C13: 46238 | D13: Tue | I13: =I12+G13 -> 0 | K13: Emergency Buffer | L13: ='Monthly Budget'!D10 -> 0 | M13: =SUMIF(E:E,K13,G:G) -> 0 | N13: =IF(M13>L13,"OVER",IF(M13>L13*0.9,"WARN","OK")) -> 0
B14: 5 | C14: 46239 | D14: Wed | I14: =I13+G14 -> 0 | K14: Personal Care | L14: ='Monthly Budget'!D11 -> 0 | M14: =SUMIF(E:E,K14,G:G) -> 0 | N14: =IF(M14>L14,"OVER",IF(M14>L14*0.9,"WARN","OK")) -> 0
B15: 6 | C15: 46240 | D15: Thu | I15: =I14+G15 -> 0 | K15: Personal Savings | L15: ='Monthly Budget'!D12 -> 0 | M15: =SUMIF(E:E,K15,G:G) -> 0 | N15: =IF(M15>L15,"OVER",IF(M15>L15*0.9,"WARN","OK")) -> 0
B16: 7 | C16: 46241 | D16: Fri | I16: =I15+G16 -> 0 | K16: Miscellaneous | L16: ='Monthly Budget'!D13 -> 0 | M16: =SUMIF(E:E,K16,G:G) -> 0 | N16: =IF(M16>L16,"OVER",IF(M16>L16*0.9,"WARN","OK")) -> 0
B17: 8 | C17: 46242 | D17: Sat | I17: =I16+G17 -> 0 | K17: TOTAL | L17: =SUM(L6:L16) -> 0 | M17: =SUM(M6:M16) -> 0
B18: 9 | C18: 46243 | D18: Sun | I18: =I17+G18 -> 0
B19: 10 | C19: 46244 | D19: Mon | I19: =I18+G19 -> 0
B20: 11 | C20: 46245 | D20: Tue | I20: =I19+G20 -> 0
B21: 12 | C21: 46246 | D21: Wed | I21: =I20+G21 -> 0
B22: 13 | C22: 46247 | D22: Thu | I22: =I21+G22 -> 0
B23: 14 | C23: 46248 | D23: Fri | I23: =I22+G23 -> 0
B24: 15 | C24: 46249 | D24: Sat | I24: =I23+G24 -> 0
B25: 16 | C25: 46250 | D25: Sun | I25: =I24+G25 -> 0
B26: 17 | C26: 46251 | D26: Mon | I26: =I25+G26 -> 0
B27: 18 | C27: 46252 | D27: Tue | I27: =I26+G27 -> 0
B28: 19 | C28: 46253 | D28: Wed | I28: =I27+G28 -> 0
B29: 20 | C29: 46254 | D29: Thu | I29: =I28+G29 -> 0
... B40: 31 | C40: 46265 | D40: Mon | I40: =I39+G40 -> 0
F41: MONTH TOTAL: | G41: =SUM(G10:G40) -> 0

Sheet September 2026
B1: SEPTEMBER 2026 EXPENSE TRACKER
B2: September 01 - September 30, 2026 (30 days)
B4: MONTH BALANCE & INCOME | F4: INCOME TRACKING | K4: September CATEGORY BREAKDOWN
B5: Opening Balance: | C5: 0 | F5: Salary (Fixed): | G5: 60000 | H5: Currency: | I5: =Dashboard!$N$2 -> 0 | K5: Category | L5: Budget | M5: Spent | N5: Status
B6: Closing Balance: | C6: 0 | F6: Freelance Income: | G6: 0 | H6: Currency: | I6: CZK | K6: Rent + Utilities | L6: ='Monthly Budget'!D3 -> 0 | M6: =SUMIF(E:E,K6,G:G) -> 0 | N6: =IF(M6>L6,"OVER",IF(M6>L6*0.9,"WARN","OK")) -> 0
B7: Net Change: | C7: =C6-C5 -> 0 | F7: Total Income: | G7: =G5+G6 -> 0 | K7: Electricity Deposit | L7: ='Monthly Budget'!D4 -> 0 | M7: =SUMIF(E:E,K7,G:G) -> 0 | N7: =IF(M7>L7,"OVER",IF(M7>L7*0.9,"WARN","OK")) -> 0
K8: Internet & Phone Bills | L8: ='Monthly Budget'!D5 -> 0 | M8: =SUMIF(E:E,K8,G:G) -> 0 | N8: =IF(M8>L8,"OVER",IF(M8>L8*0.9,"WARN","OK")) -> 0
B9: # | C9: Date | D9: Day | E9: Category | F9: Description | G9: Amount | H9: Payment | I9: Running Total | K9: Food & Groceries | L9: ='Monthly Budget'!D6 -> 0 | M9: =SUMIF(E:E,K9,G:G) -> 0 | N9: =IF(M9>L9,"OVER",IF(M9>L9*0.9,"WARN","OK")) -> 0
B10: 1 | C10: 46266 | D10: Tue | I10: =G10 -> 0 | K10: Investments | L10: ='Monthly Budget'!D7 -> 0 | M10: =SUMIF(E:E,K10,G:G) -> 0 | N10: =IF(M10>L10,"OVER",IF(M10>L10*0.9,"WARN","OK")) -> 0
B11: 2 | C11: 46267 | D11: Wed | I11: =I10+G11 -> 0 | K11: Date Nights | L11: ='Monthly Budget'!D8 -> 0 | M11: =SUMIF(E:E,K11,G:G) -> 0 | N11: =IF(M11>L11,"OVER",IF(M11>L11*0.9,"WARN","OK")) -> 0
B12: 3 | C12: 46268 | D12: Thu | I12: =I11+G12 -> 0 | K12: Annual Costs Savings | L12: ='Monthly Budget'!D9 -> 0 | M12: =SUMIF(E:E,K12,G:G) -> 0 | N12: =IF(M12>L12,"OVER",IF(M12>L12*0.9,"WARN","OK")) -> 0
B13: 4 | C13: 46269 | D13: Fri | I13: =I12+G13 -> 0 | K13: Emergency Buffer | L13: ='Monthly Budget'!D10 -> 0 | M13: =SUMIF(E:E,K13,G:G) -> 0 | N13: =IF(M13>L13,"OVER",IF(M13>L13*0.9,"WARN","OK")) -> 0
B14: 5 | C14: 46270 | D14: Sat | I14: =I13+G14 -> 0 | K14: Personal Care | L14: ='Monthly Budget'!D11 -> 0 | M14: =SUMIF(E:E,K14,G:G) -> 0 | N14: =IF(M14>L14,"OVER",IF(M14>L14*0.9,"WARN","OK")) -> 0
B15: 6 | C15: 46271 | D15: Sun | I15: =I14+G15 -> 0 | K15: Personal Savings | L15: ='Monthly Budget'!D12 -> 0 | M15: =SUMIF(E:E,K15,G:G) -> 0 | N15: =IF(M15>L15,"OVER",IF(M15>L15*0.9,"WARN","OK")) -> 0
B16: 7 | C16: 46272 | D16: Mon | I16: =I15+G16 -> 0 | K16: Miscellaneous | L16: ='Monthly Budget'!D13 -> 0 | M16: =SUMIF(E:E,K16,G:G) -> 0 | N16: =IF(M16>L16,"OVER",IF(M16>L16*0.9,"WARN","OK")) -> 0
B17: 8 | C17: 46273 | D17: Tue | I17: =I16+G17 -> 0 | K17: TOTAL | L17: =SUM(L6:L16) -> 0 | M17: =SUM(M6:M16) -> 0
B18: 9 | C18: 46274 | D18: Wed | I18: =I17+G18 -> 0
B19: 10 | C19: 46275 | D19: Thu | I19: =I18+G19 -> 0
B20: 11 | C20: 46276 | D20: Fri | I20: =I19+G20 -> 0
B21: 12 | C21: 46277 | D21: Sat | I21: =I20+G21 -> 0
B22: 13 | C22: 46278 | D22: Sun | I22: =I21+G22 -> 0
B23: 14 | C23: 46279 | D23: Mon | I23: =I22+G23 -> 0
B24: 15 | C24: 46280 | D24: Tue | I24: =I23+G24 -> 0
B25: 16 | C25: 46281 | D25: Wed | I25: =I24+G25 -> 0
B26: 17 | C26: 46282 | D26: Thu | I26: =I25+G26 -> 0
B27: 18 | C27: 46283 | D27: Fri | I27: =I26+G27 -> 0
B28: 19 | C28: 46284 | D28: Sat | I28: =I27+G28 -> 0
B29: 20 | C29: 46285 | D29: Sun | I29: =I28+G29 -> 0
... B39: 30 | C39: 46295 | D39: Wed | I39: =I38+G39 -> 0
F40: MONTH TOTAL: | G40: =SUM(G10:G39) -> 0

Sheet October 2026
B1: OCTOBER 2026 EXPENSE TRACKER
B2: October 01 - October 31, 2026 (31 days)
B4: MONTH BALANCE & INCOME | F4: INCOME TRACKING | K4: October CATEGORY BREAKDOWN
B5: Opening Balance: | C5: 0 | F5: Salary (Fixed): | G5: 60000 | H5: Currency: | I5: =Dashboard!$N$2 -> 0 | K5: Category | L5: Budget | M5: Spent | N5: Status
B6: Closing Balance: | C6: 0 | F6: Freelance Income: | G6: 0 | H6: Currency: | I6: CZK | K6: Rent + Utilities | L6: ='Monthly Budget'!D3 -> 0 | M6: =SUMIF(E:E,K6,G:G) -> 0 | N6: =IF(M6>L6,"OVER",IF(M6>L6*0.9,"WARN","OK")) -> 0
B7: Net Change: | C7: =C6-C5 -> 0 | F7: Total Income: | G7: =G5+G6 -> 0 | K7: Electricity Deposit | L7: ='Monthly Budget'!D4 -> 0 | M7: =SUMIF(E:E,K7,G:G) -> 0 | N7: =IF(M7>L7,"OVER",IF(M7>L7*0.9,"WARN","OK")) -> 0
K8: Internet & Phone Bills | L8: ='Monthly Budget'!D5 -> 0 | M8: =SUMIF(E:E,K8,G:G) -> 0 | N8: =IF(M8>L8,"OVER",IF(M8>L8*0.9,"WARN","OK")) -> 0
B9: # | C9: Date | D9: Day | E9: Category | F9: Description | G9: Amount | H9: Payment | I9: Running Total | K9: Food & Groceries | L9: ='Monthly Budget'!D6 -> 0 | M9: =SUMIF(E:E,K9,G:G) -> 0 | N9: =IF(M9>L9,"OVER",IF(M9>L9*0.9,"WARN","OK")) -> 0
B10: 1 | C10: 46296 | D10: Thu | I10: =G10 -> 0 | K10: Investments | L10: ='Monthly Budget'!D7 -> 0 | M10: =SUMIF(E:E,K10,G:G) -> 0 | N10: =IF(M10>L10,"OVER",IF(M10>L10*0.9,"WARN","OK")) -> 0
B11: 2 | C11: 46297 | D11: Fri | I11: =I10+G11 -> 0 | K11: Date Nights | L11: ='Monthly Budget'!D8 -> 0 | M11: =SUMIF(E:E,K11,G:G) -> 0 | N11: =IF(M11>L11,"OVER",IF(M11>L11*0.9,"WARN","OK")) -> 0
B12: 3 | C12: 46298 | D12: Sat | I12: =I11+G12 -> 0 | K12: Annual Costs Savings | L12: ='Monthly Budget'!D9 -> 0 | M12: =SUMIF(E:E,K12,G:G) -> 0 | N12: =IF(M12>L12,"OVER",IF(M12>L12*0.9,"WARN","OK")) -> 0
B13: 4 | C13: 46299 | D13: Sun | I13: =I12+G13 -> 0 | K13: Emergency Buffer | L13: ='Monthly Budget'!D10 -> 0 | M13: =SUMIF(E:E,K13,G:G) -> 0 | N13: =IF(M13>L13,"OVER",IF(M13>L13*0.9,"WARN","OK")) -> 0
B14: 5 | C14: 46300 | D14: Mon | I14: =I13+G14 -> 0 | K14: Personal Care | L14: ='Monthly Budget'!D11 -> 0 | M14: =SUMIF(E:E,K14,G:G) -> 0 | N14: =IF(M14>L14,"OVER",IF(M14>L14*0.9,"WARN","OK")) -> 0
B15: 6 | C15: 46301 | D15: Tue | I15: =I14+G15 -> 0 | K15: Personal Savings | L15: ='Monthly Budget'!D12 -> 0 | M15: =SUMIF(E:E,K15,G:G) -> 0 | N15: =IF(M15>L15,"OVER",IF(M15>L15*0.9,"WARN","OK")) -> 0
B16: 7 | C16: 46302 | D16: Wed | I16: =I15+G16 -> 0 | K16: Miscellaneous | L16: ='Monthly Budget'!D13 -> 0 | M16: =SUMIF(E:E,K16,G:G) -> 0 | N16: =IF(M16>L16,"OVER",IF(M16>L16*0.9,"WARN","OK")) -> 0
B17: 8 | C17: 46303 | D17: Thu | I17: =I16+G17 -> 0 | K17: TOTAL | L17: =SUM(L6:L16) -> 0 | M17: =SUM(M6:M16) -> 0
B18: 9 | C18: 46304 | D18: Fri | I18: =I17+G18 -> 0
B19: 10 | C19: 46305 | D19: Sat | I19: =I18+G19 -> 0
B20: 11 | C20: 46306 | D20: Sun | I20: =I19+G20 -> 0
B21: 12 | C21: 46307 | D21: Mon | I21: =I20+G21 -> 0
B22: 13 | C22: 46308 | D22: Tue | I22: =I21+G22 -> 0
B23: 14 | C23: 46309 | D23: Wed | I23: =I22+G23 -> 0
B24: 15 | C24: 46310 | D24: Thu | I24: =I23+G24 -> 0
B25: 16 | C25: 46311 | D25: Fri | I25: =I24+G25 -> 0
B26: 17 | C26: 46312 | D26: Sat | I26: =I25+G26 -> 0
B27: 18 | C27: 46313 | D27: Sun | I27: =I26+G27 -> 0
B28: 19 | C28: 46314 | D28: Mon | I28: =I27+G28 -> 0
B29: 20 | C29: 46315 | D29: Tue | I29: =I28+G29 -> 0
... B40: 31 | C40: 46326 | D40: Sat | I40: =I39+G40 -> 0
F41: MONTH TOTAL: | G41: =SUM(G10:G40) -> 0

Sheet November 2026
B1: NOVEMBER 2026 EXPENSE TRACKER
B2: November 01 - November 30, 2026 (30 days)
B4: MONTH BALANCE & INCOME | F4: INCOME TRACKING | K4: November CATEGORY BREAKDOWN
B5: Opening Balance: | C5: 0 | F5: Salary (Fixed): | G5: 60000 | H5: Currency: | I5: =Dashboard!$N$2 -> 0 | K5: Category | L5: Budget | M5: Spent | N5: Status
B6: Closing Balance: | C6: 0 | F6: Freelance Income: | G6: 0 | H6: Currency: | I6: CZK | K6: Rent + Utilities | L6: ='Monthly Budget'!D3 -> 0 | M6: =SUMIF(E:E,K6,G:G) -> 0 | N6: =IF(M6>L6,"OVER",IF(M6>L6*0.9,"WARN","OK")) -> 0
B7: Net Change: | C7: =C6-C5 -> 0 | F7: Total Income: | G7: =G5+G6 -> 0 | K7: Electricity Deposit | L7: ='Monthly Budget'!D4 -> 0 | M7: =SUMIF(E:E,K7,G:G) -> 0 | N7: =IF(M7>L7,"OVER",IF(M7>L7*0.9,"WARN","OK")) -> 0
K8: Internet & Phone Bills | L8: ='Monthly Budget'!D5 -> 0 | M8: =SUMIF(E:E,K8,G:G) -> 0 | N8: =IF(M8>L8,"OVER",IF(M8>L8*0.9,"WARN","OK")) -> 0
B9: # | C9: Date | D9: Day | E9: Category | F9: Description | G9: Amount | H9: Payment | I9: Running Total | K9: Food & Groceries | L9: ='Monthly Budget'!D6 -> 0 | M9: =SUMIF(E:E,K9,G:G) -> 0 | N9: =IF(M9>L9,"OVER",IF(M9>L9*0.9,"WARN","OK")) -> 0
B10: 1 | C10: 46327 | D10: Sun | I10: =G10 -> 0 | K10: Investments | L10: ='Monthly Budget'!D7 -> 0 | M10: =SUMIF(E:E,K10,G:G) -> 0 | N10: =IF(M10>L10,"OVER",IF(M10>L10*0.9,"WARN","OK")) -> 0
B11: 2 | C11: 46328 | D11: Mon | I11: =I10+G11 -> 0 | K11: Date Nights | L11: ='Monthly Budget'!D8 -> 0 | M11: =SUMIF(E:E,K11,G:G) -> 0 | N11: =IF(M11>L11,"OVER",IF(M11>L11*0.9,"WARN","OK")) -> 0
B12: 3 | C12: 46329 | D12: Tue | I12: =I11+G12 -> 0 | K12: Annual Costs Savings | L12: ='Monthly Budget'!D9 -> 0 | M12: =SUMIF(E:E,K12,G:G) -> 0 | N12: =IF(M12>L12,"OVER",IF(M12>L12*0.9,"WARN","OK")) -> 0
B13: 4 | C13: 46330 | D13: Wed | I13: =I12+G13 -> 0 | K13: Emergency Buffer | L13: ='Monthly Budget'!D10 -> 0 | M13: =SUMIF(E:E,K13,G:G) -> 0 | N13: =IF(M13>L13,"OVER",IF(M13>L13*0.9,"WARN","OK")) -> 0
B14: 5 | C14: 46331 | D14: Thu | I14: =I13+G14 -> 0 | K14: Personal Care | L14: ='Monthly Budget'!D11 -> 0 | M14: =SUMIF(E:E,K14,G:G) -> 0 | N14: =IF(M14>L14,"OVER",IF(M14>L14*0.9,"WARN","OK")) -> 0
B15: 6 | C15: 46332 | D15: Fri | I15: =I14+G15 -> 0 | K15: Personal Savings | L15: ='Monthly Budget'!D12 -> 0 | M15: =SUMIF(E:E,K15,G:G) -> 0 | N15: =IF(M15>L15,"OVER",IF(M15>L15*0.9,"WARN","OK")) -> 0
B16: 7 | C16: 46333 | D16: Sat | I16: =I15+G16 -> 0 | K16: Miscellaneous | L16: ='Monthly Budget'!D13 -> 0 | M16: =SUMIF(E:E,K16,G:G) -> 0 | N16: =IF(M16>L16,"OVER",IF(M16>L16*0.9,"WARN","OK")) -> 0
B17: 8 | C17: 46334 | D17: Sun | I17: =I16+G17 -> 0 | K17: TOTAL | L17: =SUM(L6:L16) -> 0 | M17: =SUM(M6:M16) -> 0
B18: 9 | C18: 46335 | D18: Mon | I18: =I17+G18 -> 0
B19: 10 | C19: 46336 | D19: Tue | I19: =I18+G19 -> 0
B20: 11 | C20: 46337 | D20: Wed | I20: =I19+G20 -> 0
B21: 12 | C21: 46338 | D21: Thu | I21: =I20+G21 -> 0
B22: 13 | C22: 46339 | D22: Fri | I22: =I21+G22 -> 0
B23: 14 | C23: 46340 | D23: Sat | I23: =I22+G23 -> 0
B24: 15 | C24: 46341 | D24: Sun | I24: =I23+G24 -> 0
B25: 16 | C25: 46342 | D25: Mon | I25: =I24+G25 -> 0
B26: 17 | C26: 46343 | D26: Tue | I26: =I25+G26 -> 0
B27: 18 | C27: 46344 | D27: Wed | I27: =I26+G27 -> 0
B28: 19 | C28: 46345 | D28: Thu | I28: =I27+G28 -> 0
B29: 20 | C29: 46346 | D29: Fri | I29: =I28+G29 -> 0
... B39: 30 | C39: 46356 | D39: Mon | I39: =I38+G39 -> 0
F40: MONTH TOTAL: | G40: =SUM(G10:G39) -> 0

Sheet December 2026
B1: DECEMBER 2026 EXPENSE TRACKER
B2: December 01 - December 31, 2026 (31 days)
B4: MONTH BALANCE & INCOME | F4: INCOME TRACKING | K4: December CATEGORY BREAKDOWN
B5: Opening Balance: | C5: 0 | F5: Salary (Fixed): | G5: 60000 | H5: Currency: | I5: =Dashboard!$N$2 -> 0 | K5: Category | L5: Budget | M5: Spent | N5: Status
B6: Closing Balance: | C6: 0 | F6: Freelance Income: | G6: 0 | H6: Currency: | I6: CZK | K6: Rent + Utilities | L6: ='Monthly Budget'!D3 -> 0 | M6: =SUMIF(E:E,K6,G:G) -> 0 | N6: =IF(M6>L6,"OVER",IF(M6>L6*0.9,"WARN","OK")) -> 0
B7: Net Change: | C7: =C6-C5 -> 0 | F7: Total Income: | G7: =G5+G6 -> 0 | K7: Electricity Deposit | L7: ='Monthly Budget'!D4 -> 0 | M7: =SUMIF(E:E,K7,G:G) -> 0 | N7: =IF(M7>L7,"OVER",IF(M7>L7*0.9,"WARN","OK")) -> 0
K8: Internet & Phone Bills | L8: ='Monthly Budget'!D5 -> 0 | M8: =SUMIF(E:E,K8,G:G) -> 0 | N8: =IF(M8>L8,"OVER",IF(M8>L8*0.9,"WARN","OK")) -> 0
B9: # | C9: Date | D9: Day | E9: Category | F9: Description | G9: Amount | H9: Payment | I9: Running Total | K9: Food & Groceries | L9: ='Monthly Budget'!D6 -> 0 | M9: =SUMIF(E:E,K9,G:G) -> 0 | N9: =IF(M9>L9,"OVER",IF(M9>L9*0.9,"WARN","OK")) -> 0
B10: 1 | C10: 46357 | D10: Tue | I10: =G10 -> 0 | K10: Investments | L10: ='Monthly Budget'!D7 -> 0 | M10: =SUMIF(E:E,K10,G:G) -> 0 | N10: =IF(M10>L10,"OVER",IF(M10>L10*0.9,"WARN","OK")) -> 0
B11: 2 | C11: 46358 | D11: Wed | I11: =I10+G11 -> 0 | K11: Date Nights | L11: ='Monthly Budget'!D8 -> 0 | M11: =SUMIF(E:E,K11,G:G) -> 0 | N11: =IF(M11>L11,"OVER",IF(M11>L11*0.9,"WARN","OK")) -> 0
B12: 3 | C12: 46359 | D12: Thu | I12: =I11+G12 -> 0 | K12: Annual Costs Savings | L12: ='Monthly Budget'!D9 -> 0 | M12: =SUMIF(E:E,K12,G:G) -> 0 | N12: =IF(M12>L12,"OVER",IF(M12>L12*0.9,"WARN","OK")) -> 0
B13: 4 | C13: 46360 | D13: Fri | I13: =I12+G13 -> 0 | K13: Emergency Buffer | L13: ='Monthly Budget'!D10 -> 0 | M13: =SUMIF(E:E,K13,G:G) -> 0 | N13: =IF(M13>L13,"OVER",IF(M13>L13*0.9,"WARN","OK")) -> 0
B14: 5 | C14: 46361 | D14: Sat | I14: =I13+G14 -> 0 | K14: Personal Care | L14: ='Monthly Budget'!D11 -> 0 | M14: =SUMIF(E:E,K14,G:G) -> 0 | N14: =IF(M14>L14,"OVER",IF(M14>L14*0.9,"WARN","OK")) -> 0
B15: 6 | C15: 46362 | D15: Sun | I15: =I14+G15 -> 0 | K15: Personal Savings | L15: ='Monthly Budget'!D12 -> 0 | M15: =SUMIF(E:E,K15,G:G) -> 0 | N15: =IF(M15>L15,"OVER",IF(M15>L15*0.9,"WARN","OK")) -> 0
B16: 7 | C16: 46363 | D16: Mon | I16: =I15+G16 -> 0 | K16: Miscellaneous | L16: ='Monthly Budget'!D13 -> 0 | M16: =SUMIF(E:E,K16,G:G) -> 0 | N16: =IF(M16>L16,"OVER",IF(M16>L16*0.9,"WARN","OK")) -> 0
B17: 8 | C17: 46364 | D17: Tue | I17: =I16+G17 -> 0 | K17: TOTAL | L17: =SUM(L6:L16) -> 0 | M17: =SUM(M6:M16) -> 0
B18: 9 | C18: 46365 | D18: Wed | I18: =I17+G18 -> 0
B19: 10 | C19: 46366 | D19: Thu | I19: =I18+G19 -> 0
B20: 11 | C20: 46367 | D20: Fri | I20: =I19+G20 -> 0
B21: 12 | C21: 46368 | D21: Sat | I21: =I20+G21 -> 0
B22: 13 | C22: 46369 | D22: Sun | I22: =I21+G22 -> 0
B23: 14 | C23: 46370 | D23: Mon | I23: =I22+G23 -> 0
B24: 15 | C24: 46371 | D24: Tue | I24: =I23+G24 -> 0
B25: 16 | C25: 46372 | D25: Wed | I25: =I24+G25 -> 0
B26: 17 | C26: 46373 | D26: Thu | I26: =I25+G26 -> 0
B27: 18 | C27: 46374 | D27: Fri | I27: =I26+G27 -> 0
B28: 19 | C28: 46375 | D28: Sat | I28: =I27+G28 -> 0
B29: 20 | C29: 46376 | D29: Sun | I29: =I28+G29 -> 0
... B40: 31 | C40: 46387 | D40: Thu | I40: =I39+G40 -> 0
F41: MONTH TOTAL: | G41: =SUM(G10:G40) -> 0

Sheet Budget vs Actual
B1: BUDGET VS ACTUAL - YEAR 2026
B2: January 1st - December 31st
B3: Category | C3: Annual Budget | D3: YTD Actual | E3: Remaining | F3: % Used | G3: % of Spend | H3: Status
B4: Rent + Utilities | C4: ='Monthly Budget'!D3*12 -> 0 | D4: ='January 2026'!M6+'February 2026'!M6+'March 2026'!M6+'April 2026'!M6+'May 2026'!M6+'June 2026'!M6+'July 2026'!M6+'August 2026'!M6+'September 2026'!M6+'October 2026'!M6+'November 2026'!M6+'December 2026'!M6 -> 0 | E4: =C4-D4 -> 0 | F4: =IFERROR(IF(C4>0,D4/C4,0),0) -> 0 | G4: =IFERROR(IF($D$15>0,D4/$D$15,0),0) -> 0 | H4: =IF(D4>C4,"OVER BUDGET",IF(D4>C4*0.9,"WARNING",IF(D4>C4*0.75,"CAUTION","ON TRACK"))) -> 0
B5: Electricity Deposit | C5: ='Monthly Budget'!D4*12 -> 0 | D5: ='January 2026'!M7+'February 2026'!M7+'March 2026'!M7+'April 2026'!M7+'May 2026'!M7+'June 2026'!M7+'July 2026'!M7+'August 2026'!M7+'September 2026'!M7+'October 2026'!M7+'November 2026'!M7+'December 2026'!M7 -> 0 | E5: =C5-D5 -> 0 | F5: =IFERROR(IF(C5>0,D5/C5,0),0) -> 0 | G5: =IFERROR(IF($D$15>0,D5/$D$15,0),0) -> 0 | H5: =IF(D5>C5,"OVER BUDGET",IF(D5>C5*0.9,"WARNING",IF(D5>C5*0.75,"CAUTION","ON TRACK"))) -> 0
B6: Internet & Phone Bills | C6: ='Monthly Budget'!D5*12 -> 0 | D6: ='January 2026'!M8+'February 2026'!M8+'March 2026'!M8+'April 2026'!M8+'May 2026'!M8+'June 2026'!M8+'July 2026'!M8+'August 2026'!M8+'September 2026'!M8+'October 2026'!M8+'November 2026'!M8+'December 2026'!M8 -> 0 | E6: =C6-D6 -> 0 | F6: =IFERROR(IF(C6>0,D6/C6,0),0) -> 0 | G6: =IFERROR(IF($D$15>0,D6/$D$15,0),0) -> 0 | H6: =IF(D6>C6,"OVER BUDGET",IF(D6>C6*0.9,"WARNING",IF(D6>C6*0.75,"CAUTION","ON TRACK"))) -> 0
B7: Food & Groceries | C7: ='Monthly Budget'!D6*12 -> 0 | D7: ='January 2026'!M9+'February 2026'!M9+'March 2026'!M9+'April 2026'!M9+'May 2026'!M9+'June 2026'!M9+'July 2026'!M9+'August 2026'!M9+'September 2026'!M9+'October 2026'!M9+'November 2026'!M9+'December 2026'!M9 -> 0 | E7: =C7-D7 -> 0 | F7: =IFERROR(IF(C7>0,D7/C7,0),0) -> 0 | G7: =IFERROR(IF($D$15>0,D7/$D$15,0),0) -> 0 | H7: =IF(D7>C7,"OVER BUDGET",IF(D7>C7*0.9,"WARNING",IF(D7>C7*0.75,"CAUTION","ON TRACK"))) -> 0
B8: Investments | C8: ='Monthly Budget'!D7*12 -> 0 | D8: ='January 2026'!M10+'February 2026'!M10+'March 2026'!M10+'April 2026'!M10+'May 2026'!M10+'June 2026'!M10+'July 2026'!M10+'August 2026'!M10+'September 2026'!M10+'October 2026'!M10+'November 2026'!M10+'December 2026'!M10 -> 0 | E8: =C8-D8 -> 0 | F8: =IFERROR(IF(C8>0,D8/C8,0),0) -> 0 | G8: =IFERROR(IF($D$15>0,D8/$D$15,0),0) -> 0 | H8: =IF(D8>C8,"OVER BUDGET",IF(D8>C8*0.9,"WARNING",IF(D8>C8*0.75,"CAUTION","ON TRACK"))) -> 0
B9: Date Nights | C9: ='Monthly Budget'!D8*12 -> 0 | D9: ='January 2026'!M11+'February 2026'!M11+'March 2026'!M11+'April 2026'!M11+'May 2026'!M11+'June 2026'!M11+'July 2026'!M11+'August 2026'!M11+'September 2026'!M11+'October 2026'!M11+'November 2026'!M11+'December 2026'!M11 -> 0 | E9: =C9-D9 -> 0 | F9: =IFERROR(IF(C9>0,D9/C9,0),0) -> 0 | G9: =IFERROR(IF($D$15>0,D9/$D$15,0),0) -> 0 | H9: =IF(D9>C9,"OVER BUDGET",IF(D9>C9*0.9,"WARNING",IF(D9>C9*0.75,"CAUTION","ON TRACK"))) -> 0
B10: Annual Costs Savings | C10: ='Monthly Budget'!D9*12 -> 0 | D10: ='January 2026'!M12+'February 2026'!M12+'March 2026'!M12+'April 2026'!M12+'May 2026'!M12+'June 2026'!M12+'July 2026'!M12+'August 2026'!M12+'September 2026'!M12+'October 2026'!M12+'November 2026'!M12+'December 2026'!M12 -> 0 | E10: =C10-D10 -> 0 | F10: =IFERROR(IF(C10>0,D10/C10,0),0) -> 0 | G10: =IFERROR(IF($D$15>0,D10/$D$15,0),0) -> 0 | H10: =IF(D10>C10,"OVER BUDGET",IF(D10>C10*0.9,"WARNING",IF(D10>C10*0.75,"CAUTION","ON TRACK"))) -> 0
B11: Emergency Buffer | C11: ='Monthly Budget'!D10*12 -> 0 | D11: ='January 2026'!M13+'February 2026'!M13+'March 2026'!M13+'April 2026'!M13+'May 2026'!M13+'June 2026'!M13+'July 2026'!M13+'August 2026'!M13+'September 2026'!M13+'October 2026'!M13+'November 2026'!M13+'December 2026'!M13 -> 0 | E11: =C11-D11 -> 0 | F11: =IFERROR(IF(C11>0,D11/C11,0),0) -> 0 | G11: =IFERROR(IF($D$15>0,D11/$D$15,0),0) -> 0 | H11: =IF(D11>C11,"OVER BUDGET",IF(D11>C11*0.9,"WARNING",IF(D11>C11*0.75,"CAUTION","ON TRACK"))) -> 0
B12: Personal Care | C12: ='Monthly Budget'!D11*12 -> 0 | D12: ='January 2026'!M14+'February 2026'!M14+'March 2026'!M14+'April 2026'!M14+'May 2026'!M14+'June 2026'!M14+'July 2026'!M14+'August 2026'!M14+'September 2026'!M14+'October 2026'!M14+'November 2026'!M14+'December 2026'!M14 -> 0 | E12: =C12-D12 -> 0 | F12: =IFERROR(IF(C12>0,D12/C12,0),0) -> 0 | G12: =IFERROR(IF($D$15>0,D12/$D$15,0),0) -> 0 | H12: =IF(D12>C12,"OVER BUDGET",IF(D12>C12*0.9,"WARNING",IF(D12>C12*0.75,"CAUTION","ON TRACK"))) -> 0
